## 1. 按照一下规则合并两个数组
```
var arr1 = ['a1', 'a2', 'a3', 'b1', 'b2', 'c1', 'c2', 'd1', 'd2'];
var arr2 = ['a', 'b', 'c', 'd'];
=> ['a1', 'a2', 'a', 'a3', 'b1', b2', 'b', 'c1', 'c2', 'c', 'd1', 'd2', 'd']
function concatArr(arr1, arr2) {
  var newArr = [];
  for (var i = 0; i < arr2.length; i++) {
    var regExp1 = new RegExp('^'+ arr2[i] +'\\w+');
    var regExp2 = new RegExp('^[^'+ arr2[i] +']\\w+');
    for (var j = 0; j < arr1.length; j++) {
      if (regExp1.test(arr1[j])) {
        newArr.push(arr1[j]);
        if (regExp2.test(arr1[j+1])) {
          newArr.push(arr2[i]);
        }
      } else {
        continue;
      }
    }
  }
  return newArr;
}
```
## 2. 定义一个函数，满足以下条件:
1. add(1) = 1; 
2. add(1)(2) = 2; 
3. add(1)(2)(3) = 6;
4. add(1, 2)(3) = 6;
```
function add () {
  var arr = Array.prototype.slice.call(arguments);
  var res = arr.reduce(function(sum, item) {
    return sum * item;
  });
  var context = this;
  console.log(arr, res);
  return function() {
    return add.call(context, ...arr, ...arguments);
  };
}
```

条件改变一下，同属一个参数列表的参数相乘，不同的参数列表相加，即：
1. add(1, 2)(3) = 1 x 2 + 3
2. add(1)(2)(3) = 1 + 2 + 3
3. add(1, 2, 3) = 1 x 2 x 3
```
function add () {
  var arr = Array.prototype.slice.call(arguments);
  var context = this;
  return function() {
    var res = fn.bind(context, arr, ...arguments);
    if (typeof res == 'function') {
      return res();
    }
    return res;
  };
}
function fn() {
  var arr = Array.prototype.slice.call(arguments);
  var sum = 0;
  arr.forEach(function(item) {
    if (Array.isArray(item)) {
      sum = item.reduce(function(sum, item) {
        return sum * item;
      });
    } else {
      sum += item; 
    }
  })
  return sum;
}
add(1)(2)(3);  // 6
add(1, 2)(3); // 5
```

## 3. 打印结果
```
(function() {
  let a;
  let b;
  try{
    throw new TypeError();
  } catch(a) {
    a = 1; b = 2;
    console.log(a);
  }
  console.log(a);
  console.log(b);
})();
```
*=> 1 undefined 2*
解题分析：
1. try ... catch 处理 try 语句可能出现的异常，任何抛出的异常都会进入 catch 子块。
2. try 语句有任何异常，控制立即转向 catch 子句，如果没有异常会跳过 catch 子句，保证执行不会中断
3. catch 块会保存try语句抛出的制定值作为标识符，标识符仅在catch块执行时存在，执行完毕后不再有用。
4. 任何给定的异常只会被离它最近的封闭 catch 块捕获一次
5. 按执行顺序，出现异常进入catch，标识符a与全局变量a重名，因此catch中的a是标识符，b是全局变量，标识符a只在catch中起作用，变量a一直都是undefined。 